Workbook
Name all_ref_fields_have_text: DO_NOT_EDIT!$B$8
Name All_ref_fields_not_errors: DO_NOT_EDIT!$B$7
Name CoC: DO_NOT_EDIT!$B$2
Name Date_of_Count: DO_NOT_EDIT!$B$4
Name HeadingLine2: DO_NOT_EDIT!$D$2
Name HeadingLine3: DO_NOT_EDIT!$D$3
Name HeadingLine4: DO_NOT_EDIT!$D$4
Name HudNum: DO_NOT_EDIT!$B$1
Name PIT_Count_Type: DO_NOT_EDIT!$B$5
Name show_heading_section: DO_NOT_EDIT!$B$9
Name year: DO_NOT_EDIT!$B$3

Sheet README
A1: PIT Summary Report
A2: =HeadingLine2
A3: =HeadingLine3 -> PASTE DATA INTO THE 'PitRawData' TAB TO POPULATE THIS TEMPLATE.
A4: =HeadingLine4
A6: Note on this Template
A12: How To Populate This Template
A21: Additional Notes

Sheet PitRawData

Sheet All_AC
A1: PIT Summary Report
A2: =HeadingLine2
A3: =HeadingLine3 -> PASTE DATA INTO THE 'PitRawData' TAB TO POPULATE THIS TEMPLATE.
A4: =HeadingLine4
A6: All Persons: Persons in Households with at least one Adult and one Child ("AC")
B8: Sheltered | D8: Unsheltered | E8: Total
A9: Persons and Households | B9: Emergency | C9: Transitional
A10: Total Number of Households | B10: =IFERROR(INDEX(PitRawData!$A$1:$AMK$3,3,MATCH(G10,PitRawData!$A$1:$AMK$1,0)),"NO DATA") -> NO DATA | C10: =IFERROR(INDEX(PitRawData!$A$1:$AMK$3,3,MATCH(H10,PitRawData!$A$1:$AMK$1,0)),"NO DATA") -> NO DATA | D10: =IFERROR(INDEX(PitRawData!$A$1:$AMK$3,3,MATCH(I10,PitRawData!$A$1:$AMK$1,0)),"NO DATA") -> NO DATA | E10: =SUM(B10:D10) -> 0 | G10: householdBothEmergency | H10: householdBothTransitional | I10: householdBothUnsheltered
A11: Total Number of Persons (Adults & Children) | B11: =SUM(B12:B18) -> 0 | C11: =SUM(C12:C18) -> 0 | D11: =SUM(D12:D18) -> 0 | E11: =SUM(B11:D11) -> 0
A12: Number of Persons (under age 18) | B12: =IFERROR(INDEX(PitRawData!$A$1:$AMK$3,3,MATCH(G12,PitRawData!$A$1:$AMK$1,0)),"NO DATA") -> NO DATA | C12: =IFERROR(INDEX(PitRawData!$A$1:$AMK$3,3,MATCH(H12,PitRawData!$A$1:$AMK$1,0)),"NO DATA") -> NO DATA | D12: =IFERROR(INDEX(PitRawData!$A$1:$AMK$3,3,MATCH(I12,PitRawData!$A$1:$AMK$1,0)),"NO DATA") -> NO DATA | E12: =SUM(B12:D12) -> 0 | G12: personBothUnder18Emergency | H12: personBothUnder18Transitional | I12: personBothUnder18Unsheltered
A13: Number of Persons (18 - 24) | B13: =IFERROR(INDEX(PitRawData!$A$1:$AMK$3,3,MATCH(G13,PitRawData!$A$1:$AMK$1,0)),"NO DATA") -> NO DATA | C13: =IFERROR(INDEX(PitRawData!$A$1:$AMK$3,3,MATCH(H13,PitRawData!$A$1:$AMK$1,0)),"NO DATA") -> NO DATA | D13: =IFERROR(INDEX(PitRawData!$A$1:$AMK$3,3,MATCH(I13,PitRawData!$A$1:$AMK$1,0)),"NO DATA") -> NO DATA | E13: =SUM(B13:D13) -> 0 | G13: personBoth18To24Emergency | H13: personBoth18To24Transitional | I13: personBoth18To24Unsheltered
A14: Number of Persons (25 - 34) | B14: =IFERROR(INDEX(PitRawData!$A$1:$AMK$3,3,MATCH(G14,PitRawData!$A$1:$AMK$1,0)),"NO DATA") -> NO DATA | C14: =IFERROR(INDEX(PitRawData!$A$1:$AMK$3,3,MATCH(H14,PitRawData!$A$1:$AMK$1,0)),"NO DATA") -> NO DATA | D14: =IFERROR(INDEX(PitRawData!$A$1:$AMK$3,3,MATCH(I14,PitRawData!$A$1:$AMK$1,0)),"NO DATA") -> NO DATA | E14: =SUM(B14:D14) -> 0 | G14: personBoth25To34Emergency | H14: personBoth25To34Transitional | I14: personBoth25To34Unsheltered
A15: Number of Persons (35 - 44) | B15: =IFERROR(INDEX(PitRawData!$A$1:$AMK$3,3,MATCH(G15,PitRawData!$A$1:$AMK$1,0)),"NO DATA") -> NO DATA | C15: =IFERROR(INDEX(PitRawData!$A$1:$AMK$3,3,MATCH(H15,PitRawData!$A$1:$AMK$1,0)),"NO DATA") -> NO DATA | D15: =IFERROR(INDEX(PitRawData!$A$1:$AMK$3,3,MATCH(I15,PitRawData!$A$1:$AMK$1,0)),"NO DATA") -> NO DATA | E15: =SUM(B15:D15) -> 0 | G15: personBoth35To44Emergency | H15: personBoth35To44Transitional | I15: personBoth35To44Unsheltered
A16: Number of Persons (45 - 54) | B16: =IFERROR(INDEX(PitRawData!$A$1:$AMK$3,3,MATCH(G16,PitRawData!$A$1:$AMK$1,0)),"NO DATA") -> NO DATA | C16: =IFERROR(INDEX(PitRawData!$A$1:$AMK$3,3,MATCH(H16,PitRawData!$A$1:$AMK$1,0)),"NO DATA") -> NO DATA | D16: =IFERROR(INDEX(PitRawData!$A$1:$AMK$3,3,MATCH(I16,PitRawData!$A$1:$AMK$1,0)),"NO DATA") -> NO DATA | E16: =SUM(B16:D16) -> 0 | G16: personBoth45To54Emergency | H16: personBoth45To54Transitional | I16: personBoth45To54Unsheltered
A17: Number of Persons (55 - 64) | B17: =IFERROR(INDEX(PitRawData!$A$1:$AMK$3,3,MATCH(G17,PitRawData!$A$1:$AMK$1,0)),"NO DATA") -> NO DATA | C17: =IFERROR(INDEX(PitRawData!$A$1:$AMK$3,3,MATCH(H17,PitRawData!$A$1:$AMK$1,0)),"NO DATA") -> NO DATA | D17: =IFERROR(INDEX(PitRawData!$A$1:$AMK$3,3,MATCH(I17,PitRawData!$A$1:$AMK$1,0)),"NO DATA") -> NO DATA | E17: =SUM(B17:D17) -> 0 | G17: personBoth55To64Emergency | H17: personBoth55To64Transitional | I17: personBoth55To64Unsheltered
A18: Number of Persons (over age 64) | B18: =IFERROR(INDEX(PitRawData!$A$1:$AMK$3,3,MATCH(G18,PitRawData!$A$1:$AMK$1,0)),"NO DATA") -> NO DATA | C18: =IFERROR(INDEX(PitRawData!$A$1:$AMK$3,3,MATCH(H18,PitRawData!$A$1:$AMK$1,0)),"NO DATA") -> NO DATA | D18: =IFERROR(INDEX(PitRawData!$A$1:$AMK$3,3,MATCH(I18,PitRawData!$A$1:$AMK$1,0)),"NO DATA") -> NO DATA | E18: =SUM(B18:D18) -> 0 | G18: personBothOver64Emergency | H18: personBothOver64Transitional | I18: personBothOver64Unsheltered
B20: Sheltered | D20: Unsheltered | E20: Total
A21: Race/Ethnicity (Adults and Children) | B21: Emergency | C21: Transitional
A22: American Indian, Alaska Native, or Indigenous (only) | B22: =IFERROR(INDEX(PitRawData!$A$1:$AMK$3,3,MATCH(G22,PitRawData!$A$1:$AMK$1,0)),"NO DATA") -> NO DATA | C22: =IFERROR(INDEX(PitRawData!$A$1:$AMK$3,3,MATCH(H22,PitRawData!$A$1:$AMK$1,0)),"NO DATA") -> NO DATA | D22: =IFERROR(INDEX(PitRawData!$A$1:$AMK$3,3,MATCH(I22,PitRawData!$A$1:$AMK$1,0)),"NO DATA") -> NO DATA | E22: =SUM(B22:D22) -> 0 | G22: personBothAmericanIndianNHEmergency | H22: personBothAmericanIndianNHTransitional | I22: personBothAmericanIndianNHUnsheltered
A23: American Indian, Alaska Native, or Indigenous & Hispanic/Latina/e/o | B23: =IFERROR(INDEX(PitRawData!$A$1:$AMK$3,3,MATCH(G23,PitRawData!$A$1:$AMK$1,0)),"NO DATA") -> NO DATA | C23: =IFERROR(INDEX(PitRawData!$A$1:$AMK$3,3,MATCH(H23,PitRawData!$A$1:$AMK$1,0)),"NO DATA") -> NO DATA | D23: =IFERROR(INDEX(PitRawData!$A$1:$AMK$3,3,MATCH(I23,PitRawData!$A$1:$AMK$1,0)),"NO DATA") -> NO DATA | E23: =SUM(B23:D23) -> 0 | G23: personBothAmericanIndianHEmergency | H23: personBothAmericanIndianHTransitional | I23: personBothAmericanIndianHUnsheltered
A24: Asian or Asian American (only) | B24: =IFERROR(INDEX(PitRawData!$A$1:$AMK$3,3,MATCH(G24,PitRawData!$A$1:$AMK$1,0)),"NO DATA") -> NO DATA | C24: =IFERROR(INDEX(PitRawData!$A$1:$AMK$3,3,MATCH(H24,PitRawData!$A$1:$AMK$1,0)),"NO DATA") -> NO DATA | D24: =IFERROR(INDEX(PitRawData!$A$1:$AMK$3,3,MATCH(I24,PitRawData!$A$1:$AMK$1,0)),"NO DATA") -> NO DATA | E24: =SUM(B24:D24) -> 0 | G24: personBothAsianNHEmergency | H24: personBothAsianNHTransitional | I24: personBothAsianNHUnsheltered
A25: Asian or Asian American & Hispanic/Latina/e/o | B25: =IFERROR(INDEX(PitRawData!$A$1:$AMK$3,3,MATCH(G25,PitRawData!$A$1:$AMK$1,0)),"NO DATA") -> NO DATA | C25: =IFERROR(INDEX(PitRawData!$A$1:$AMK$3,3,MATCH(H25,PitRawData!$A$1:$AMK$1,0)),"NO DATA") -> NO DATA | D25: =IFERROR(INDEX(PitRawData!$A$1:$AMK$3,3,MATCH(I25,PitRawData!$A$1:$AMK$1,0)),"NO DATA") -> NO DATA | E25: =SUM(B25:D25) -> 0 | G25: personBothAsianHEmergency | H25: personBothAsianHTransitional | I25: personBothAsianHUnsheltered
A26: Black, African American, or African (only) | B26: =IFERROR(INDEX(PitRawData!$A$1:$AMK$3,3,MATCH(G26,PitRawData!$A$1:$AMK$1,0)),"NO DATA") -> NO DATA | C26: =IFERROR(INDEX(PitRawData!$A$1:$AMK$3,3,MATCH(H26,PitRawData!$A$1:$AMK$1,0)),"NO DATA") -> NO DATA | D26: =IFERROR(INDEX(PitRawData!$A$1:$AMK$3,3,MATCH(I26,PitRawData!$A$1:$AMK$1,0)),"NO DATA") -> NO DATA | E26: =SUM(B26:D26) -> 0 | G26: personBothBlackNHEmergency | H26: personBothBlackNHTransitional | I26: personBothBlackNHUnsheltered
A27: Black, African American, or African & Hispanic/Latina/e/o | B27: =IFERROR(INDEX(PitRawData!$A$1:$AMK$3,3,MATCH(G27,PitRawData!$A$1:$AMK$1,0)),"NO DATA") -> NO DATA | C27: =IFERROR(INDEX(PitRawData!$A$1:$AMK$3,3,MATCH(H27,PitRawData!$A$1:$AMK$1,0)),"NO DATA") -> NO DATA | D27: =IFERROR(INDEX(PitRawData!$A$1:$AMK$3,3,MATCH(I27,PitRawData!$A$1:$AMK$1,0)),"NO DATA") -> NO DATA | E27: =SUM(B27:D27) -> 0 | G27: personBothBlackHEmergency | H27: personBothBlackHTransitional | I27: personBothBlackHUnsheltered
A28: Hispanic/Latina/e/o (only) | B28: =IFERROR(INDEX(PitRawData!$A$1:$AMK$3,3,MATCH(G28,PitRawData!$A$1:$AMK$1,0)),"NO DATA") -> NO DATA | C28: =IFERROR(INDEX(PitRawData!$A$1:$AMK$3,3,MATCH(H28,PitRawData!$A$1:$AMK$1,0)),"NO DATA") -> NO DATA | D28: =IFERROR(INDEX(PitRawData!$A$1:$AMK$3,3,MATCH(I28,PitRawData!$A$1:$AMK$1,0)),"NO DATA") -> NO DATA | E28: =SUM(B28:D28) -> 0 | G28: personBothHispanicEmergency | H28: personBothHispanicTransitional | I28: personBothHispanicUnsheltered
A29: Middle Eastern or North African (only) | B29: =IFERROR(INDEX(PitRawData!$A$1:$AMK$3,3,MATCH(G29,PitRawData!$A$1:$AMK$1,0)),"NO DATA") -> NO DATA | C29: =IFERROR(INDEX(PitRawData!$A$1:$AMK$3,3,MATCH(H29,PitRawData!$A$1:$AMK$1,0)),"NO DATA") -> NO DATA | D29: =IFERROR(INDEX(PitRawData!$A$1:$AMK$3,3,MATCH(I29,PitRawData!$A$1:$AMK$1,0)),"NO DATA") -> NO DATA | E29: =SUM(B29:D29) -> 0 | G29: personBothMENANHEmergency | H29: personBothMENANHTransitional | I29: personBothMENANHUnsheltered
A30: Middle Eastern or North African & Hispanic/Latina/e/o | B30: =IFERROR(INDEX(PitRawData!$A$1:$AMK$3,3,MATCH(G30,PitRawData!$A$1:$AMK$1,0)),"NO DATA") -> NO DATA | C30: =IFERROR(INDEX(PitRawData!$A$1:$AMK$3,3,MATCH(H30,PitRawData!$A$1:$AMK$1,0)),"NO DATA") -> NO DATA | D30: =IFERROR(INDEX(PitRawData!$A$1:$AMK$3,3,MATCH(I30,PitRawData!$A$1:$AMK$1,0)),"NO DATA") -> NO DATA | E30: =SUM(B30:D30) -> 0 | G30: personBothMENAHEmergency | H30: personBothMENAHTransitional | I30: personBothMENAHUnsheltered
A31: Native Hawaiian or Pacific Islander (only) | B31: =IFERROR(INDEX(PitRawData!$A$1:$AMK$3,3,MATCH(G31,PitRawData!$A$1:$AMK$1,0)),"NO DATA") -> NO DATA | C31: =IFERROR(INDEX(PitRawData!$A$1:$AMK$3,3,MATCH(H31,PitRawData!$A$1:$AMK$1,0)),"NO DATA") -> NO DATA | D31: =IFERROR(INDEX(PitRawData!$A$1:$AMK$3,3,MATCH(I31,PitRawData!$A$1:$AMK$1,0)),"NO DATA") -> NO DATA | E31: =SUM(B31:D31) -> 0 | G31: personBothNativeHawaiianNHEmergency | H31: personBothNativeHawaiianNHTransitional | I31: personBothNativeHawaiianNHUnsheltered
A32: Native Hawaiian or Pacific Islander & Hispanic/Latina/e/o | B32: =IFERROR(INDEX(PitRawData!$A$1:$AMK$3,3,MATCH(G32,PitRawData!$A$1:$AMK$1,0)),"NO DATA") -> NO DATA | C32: =IFERROR(INDEX(PitRawData!$A$1:$AMK$3,3,MATCH(H32,PitRawData!$A$1:$AMK$1,0)),"NO DATA") -> NO DATA | D32: =IFERROR(INDEX(PitRawData!$A$1:$AMK$3,3,MATCH(I32,PitRawData!$A$1:$AMK$1,0)),"NO DATA") -> NO DATA | E32: =SUM(B32:D32) -> 0 | G32: personBothNativeHawaiianHEmergency | H32: personBothNativeHawaiianHTransitional | I32: personBothNativeHawaiianHUnsheltered
A33: White (only) | B33: =IFERROR(INDEX(PitRawData!$A$1:$AMK$3,3,MATCH(G33,PitRawData!$A$1:$AMK$1,0)),"NO DATA") -> NO DATA | C33: =IFERROR(INDEX(PitRawData!$A$1:$AMK$3,3,MATCH(H33,PitRawData!$A$1:$AMK$1,0)),"NO DATA") -> NO DATA | D33: =IFERROR(INDEX(PitRawData!$A$1:$AMK$3,3,MATCH(I33,PitRawData!$A$1:$AMK$1,0)),"NO DATA") -> NO DATA | E33: =SUM(B33:D33) -> 0 | G33: personBothWhiteNHEmergency | H33: personBothWhiteNHTransitional | I33: personBothWhiteNHUnsheltered
... A36: Multi-Racial (all other) | B36: =IFERROR(INDEX(PitRawData!$A$1:$AMK$3,3,MATCH(G36,PitRawData!$A$1:$AMK$1,0)),"NO DATA") -> NO DATA | C36: =IFERROR(INDEX(PitRawData!$A$1:$AMK$3,3,MATCH(H36,PitRawData!$A$1:$AMK$1,0)),"NO DATA") -> NO DATA | D36: =IFERROR(INDEX(PitRawData!$A$1:$AMK$3,3,MATCH(I36,PitRawData!$A$1:$AMK$1,0)),"NO DATA") -> NO DATA | E36: =SUM(B36:D36) -> 0 | G36: personBothMultipleRaceNHEmergency | H36: personBothMultipleRaceNHTransitional | I36: personBothMultipleRaceNHUnsheltered
B38: Sheltered | D38: Unsheltered | E38: Total
A39: Chronically Homeless | B39: Emergency | C39: Transitional
A40: Total number of households | B40: =IFERROR(INDEX(PitRawData!$A$1:$AMK$3,3,MATCH(G40,PitRawData!$A$1:$AMK$1,0)),"NO DATA") -> NO DATA | C40: N/A | D40: =IFERROR(INDEX(PitRawData!$A$1:$AMK$3,3,MATCH(I40,PitRawData!$A$1:$AMK$1,0)),"NO DATA") -> NO DATA | E40: =SUM(B40,D40) -> 0 | G40: personBothCronHouseholdsEmergency | I40: personBothCronHouseholdsUnsheltered
A41: Total number of persons | B41: =IFERROR(INDEX(PitRawData!$A$1:$AMK$3,3,MATCH(G41,PitRawData!$A$1:$AMK$1,0)),"NO DATA") -> NO DATA | C41: N/A | D41: =IFERROR(INDEX(PitRawData!$A$1:$AMK$3,3,MATCH(I41,PitRawData!$A$1:$AMK$1,0)),"NO DATA") -> NO DATA | E41: =SUM(B41,D41) -> 0 | G41: personBothCronPersonsEmergency | I41: personBothCronPersonsUnsheltered

Sheet All_CO
A1: PIT Summary Report
A2: =HeadingLine2
A3: =HeadingLine3 -> PASTE DATA INTO THE 'PitRawData' TAB TO POPULATE THIS TEMPLATE.
A4: =HeadingLine4
A6: All Persons: Persons in Households with only Children ("CO")
B8: Sheltered | E8: Unsheltered | F8: Total
A9: Persons and Households | B9: Emergency | C9: Transitional | D9: Safe Haven
A10: Total Number of Households | B10: =IFERROR(INDEX(PitRawData!$A$1:$AMK$3,3,MATCH(H10,PitRawData!$A$1:$AMK$1,0)),"NO DATA") -> NO DATA | C10: =IFERROR(INDEX(PitRawData!$A$1:$AMK$3,3,MATCH(I10,PitRawData!$A$1:$AMK$1,0)),"NO DATA") -> NO DATA | D10: =IFERROR(INDEX(PitRawData!$A$1:$AMK$3,3,MATCH(J10,PitRawData!$A$1:$AMK$1,0)),"NO DATA") -> NO DATA | E10: =IFERROR(INDEX(PitRawData!$A$1:$AMK$3,3,MATCH(K10,PitRawData!$A$1:$AMK$1,0)),"NO DATA") -> NO DATA | F10: =SUM(B10:E10) -> 0 | H10: householdChildEmergency | I10: householdChildTransitional | J10: householdChildSafeHaven | K10: householdChildUnsheltered
A11: Total Number of Children (under 18) | B11: =IFERROR(INDEX(PitRawData!$A$1:$AMK$3,3,MATCH(H11,PitRawData!$A$1:$AMK$1,0)),"NO DATA") -> NO DATA | C11: =IFERROR(INDEX(PitRawData!$A$1:$AMK$3,3,MATCH(I11,PitRawData!$A$1:$AMK$1,0)),"NO DATA") -> NO DATA | D11: =IFERROR(INDEX(PitRawData!$A$1:$AMK$3,3,MATCH(J11,PitRawData!$A$1:$AMK$1,0)),"NO DATA") -> NO DATA | E11: =IFERROR(INDEX(PitRawData!$A$1:$AMK$3,3,MATCH(K11,PitRawData!$A$1:$AMK$1,0)),"NO DATA") -> NO DATA | F11: =SUM(B11:E11) -> 0 | H11: personChildEmergency | I11: personChildTransitional | J11: personChildSafeHaven | K11: personChildUnsheltered
B13: Sheltered | E13: Unsheltered | F13: Total
A14: Race/Ethnicity | B14: Emergency | C14: Transitional | D14: Safe Haven
A15: American Indian, Alaska Native, or Indigenous (only) | B15: =IFERROR(INDEX(PitRawData!$A$1:$AMK$3,3,MATCH(H15,PitRawData!$A$1:$AMK$1,0)),"NO DATA") -> NO DATA | C15: =IFERROR(INDEX(PitRawData!$A$1:$AMK$3,3,MATCH(I15,PitRawData!$A$1:$AMK$1,0)),"NO DATA") -> NO DATA | D15: =IFERROR(INDEX(PitRawData!$A$1:$AMK$3,3,MATCH(J15,PitRawData!$A$1:$AMK$1,0)),"NO DATA") -> NO DATA | E15: =IFERROR(INDEX(PitRawData!$A$1:$AMK$3,3,MATCH(K15,PitRawData!$A$1:$AMK$1,0)),"NO DATA") -> NO DATA | F15: =SUM(B15:E15) -> 0 | H15: personChildAmericanIndianNHEmergency | I15: personChildAmericanIndianNHTransitional | J15: personChildAmericanIndianNHSafeHaven | K15: personChildAmericanIndianNHUnsheltered
A16: American Indian, Alaska Native, or Indigenous & Hispanic/Latina/e/o | B16: =IFERROR(INDEX(PitRawData!$A$1:$AMK$3,3,MATCH(H16,PitRawData!$A$1:$AMK$1,0)),"NO DATA") -> NO DATA | C16: =IFERROR(INDEX(PitRawData!$A$1:$AMK$3,3,MATCH(I16,PitRawData!$A$1:$AMK$1,0)),"NO DATA") -> NO DATA | D16: =IFERROR(INDEX(PitRawData!$A$1:$AMK$3,3,MATCH(J16,PitRawData!$A$1:$AMK$1,0)),"NO DATA") -> NO DATA | E16: =IFERROR(INDEX(PitRawData!$A$1:$AMK$3,3,MATCH(K16,PitRawData!$A$1:$AMK$1,0)),"NO DATA") -> NO DATA | F16: =SUM(B16:E16) -> 0 | H16: personChildAmericanIndianHEmergency | I16: personChildAmericanIndianHTransitional | J16: personChildAmericanIndianHSafeHaven | K16: personChildAmericanIndianHUnsheltered
A17: Asian or Asian American (only) | B17: =IFERROR(INDEX(PitRawData!$A$1:$AMK$3,3,MATCH(H17,PitRawData!$A$1:$AMK$1,0)),"NO DATA") -> NO DATA | C17: =IFERROR(INDEX(PitRawData!$A$1:$AMK$3,3,MATCH(I17,PitRawData!$A$1:$AMK$1,0)),"NO DATA") -> NO DATA | D17: =IFERROR(INDEX(PitRawData!$A$1:$AMK$3,3,MATCH(J17,PitRawData!$A$1:$AMK$1,0)),"NO DATA") -> NO DATA | E17: =IFERROR(INDEX(PitRawData!$A$1:$AMK$3,3,MATCH(K17,PitRawData!$A$1:$AMK$1,0)),"NO DATA") -> NO DATA | F17: =SUM(B17:E17) -> 0 | H17: personChildAsianNHEmergency | I17: personChildAsianNHTransitional | J17: personChildAsianNHSafeHaven | K17: personChildAsianNHUnsheltered
A18: Asian or Asian American & Hispanic/Latina/e/o | B18: =IFERROR(INDEX(PitRawData!$A$1:$AMK$3,3,MATCH(H18,PitRawData!$A$1:$AMK$1,0)),"NO DATA") -> NO DATA | C18: =IFERROR(INDEX(PitRawData!$A$1:$AMK$3,3,MATCH(I18,PitRawData!$A$1:$AMK$1,0)),"NO DATA") -> NO DATA | D18: =IFERROR(INDEX(PitRawData!$A$1:$AMK$3,3,MATCH(J18,PitRawData!$A$1:$AMK$1,0)),"NO DATA") -> NO DATA | E18: =IFERROR(INDEX(PitRawData!$A$1:$AMK$3,3,MATCH(K18,PitRawData!$A$1:$AMK$1,0)),"NO DATA") -> NO DATA | F18: =SUM(B18:E18) -> 0 | H18: personChildAsianHEmergency | I18: personChildAsianHTransitional | J18: personChildAsianHSafeHaven | K18: personChildAsianHUnsheltered
A19: Black, African American, or African (only) | B19: =IFERROR(INDEX(PitRawData!$A$1:$AMK$3,3,MATCH(H19,PitRawData!$A$1:$AMK$1,0)),"NO DATA") -> NO DATA | C19: =IFERROR(INDEX(PitRawData!$A$1:$AMK$3,3,MATCH(I19,PitRawData!$A$1:$AMK$1,0)),"NO DATA") -> NO DATA | D19: =IFERROR(INDEX(PitRawData!$A$1:$AMK$3,3,MATCH(J19,PitRawData!$A$1:$AMK$1,0)),"NO DATA") -> NO DATA | E19: =IFERROR(INDEX(PitRawData!$A$1:$AMK$3,3,MATCH(K19,PitRawData!$A$1:$AMK$1,0)),"NO DATA") -> NO DATA | F19: =SUM(B19:E19) -> 0 | H19: personChildBlackNHEmergency | I19: personChildBlackNHTransitional | J19: personChildBlackNHSafeHaven | K19: personChildBlackNHUnsheltered
A20: Black, African American, or African & Hispanic/Latina/e/o | B20: =IFERROR(INDEX(PitRawData!$A$1:$AMK$3,3,MATCH(H20,PitRawData!$A$1:$AMK$1,0)),"NO DATA") -> NO DATA | C20: =IFERROR(INDEX(PitRawData!$A$1:$AMK$3,3,MATCH(I20,PitRawData!$A$1:$AMK$1,0)),"NO DATA") -> NO DATA | D20: =IFERROR(INDEX(PitRawData!$A$1:$AMK$3,3,MATCH(J20,PitRawData!$A$1:$AMK$1,0)),"NO DATA") -> NO DATA | E20: =IFERROR(INDEX(PitRawData!$A$1:$AMK$3,3,MATCH(K20,PitRawData!$A$1:$AMK$1,0)),"NO DATA") -> NO DATA | F20: =SUM(B20:E20) -> 0 | H20: personChildBlackHEmergency | I20: personChildBlackHTransitional | J20: personChildBlackHSafeHaven | K20: personChildBlackHUnsheltered
A21: Hispanic/Latina/e/o (only) | B21: =IFERROR(INDEX(PitRawData!$A$1:$AMK$3,3,MATCH(H21,PitRawData!$A$1:$AMK$1,0)),"NO DATA") -> NO DATA | C21: =IFERROR(INDEX(PitRawData!$A$1:$AMK$3,3,MATCH(I21,PitRawData!$A$1:$AMK$1,0)),"NO DATA") -> NO DATA | D21: =IFERROR(INDEX(PitRawData!$A$1:$AMK$3,3,MATCH(J21,PitRawData!$A$1:$AMK$1,0)),"NO DATA") -> NO DATA | E21: =IFERROR(INDEX(PitRawData!$A$1:$AMK$3,3,MATCH(K21,PitRawData!$A$1:$AMK$1,0)),"NO DATA") -> NO DATA | F21: =SUM(B21:E21) -> 0 | H21: personChildHispanicEmergency | I21: personChildHispanicTransitional | J21: personChildHispanicSafeHaven | K21: personChildHispanicUnsheltered
A22: Middle Eastern or North African (only) | B22: =IFERROR(INDEX(PitRawData!$A$1:$AMK$3,3,MATCH(H22,PitRawData!$A$1:$AMK$1,0)),"NO DATA") -> NO DATA | C22: =IFERROR(INDEX(PitRawData!$A$1:$AMK$3,3,MATCH(I22,PitRawData!$A$1:$AMK$1,0)),"NO DATA") -> NO DATA | D22: =IFERROR(INDEX(PitRawData!$A$1:$AMK$3,3,MATCH(J22,PitRawData!$A$1:$AMK$1,0)),"NO DATA") -> NO DATA | E22: =IFERROR(INDEX(PitRawData!$A$1:$AMK$3,3,MATCH(K22,PitRawData!$A$1:$AMK$1,0)),"NO DATA") -> NO DATA | F22: =SUM(B22:E22) -> 0 | H22: personChildMENANHEmergency | I22: personChildMENANHTransitional | J22: personChildMENANHSafeHaven | K22: personChildMENANHUnsheltered
A23: Middle Eastern or North African & Hispanic/Latina/e/o | B23: =IFERROR(INDEX(PitRawData!$A$1:$AMK$3,3,MATCH(H23,PitRawData!$A$1:$AMK$1,0)),"NO DATA") -> NO DATA | C23: =IFERROR(INDEX(PitRawData!$A$1:$AMK$3,3,MATCH(I23,PitRawData!$A$1:$AMK$1,0)),"NO DATA") -> NO DATA | D23: =IFERROR(INDEX(PitRawData!$A$1:$AMK$3,3,MATCH(J23,PitRawData!$A$1:$AMK$1,0)),"NO DATA") -> NO DATA | E23: =IFERROR(INDEX(PitRawData!$A$1:$AMK$3,3,MATCH(K23,PitRawData!$A$1:$AMK$1,0)),"NO DATA") -> NO DATA | F23: =SUM(B23:E23) -> 0 | H23: personChildMENAHEmergency | I23: personChildMENAHTransitional | J23: personChildMENAHSafeHaven | K23: personChildMENAHUnsheltered
A24: Native Hawaiian or Pacific Islander (only) | B24: =IFERROR(INDEX(PitRawData!$A$1:$AMK$3,3,MATCH(H24,PitRawData!$A$1:$AMK$1,0)),"NO DATA") -> NO DATA | C24: =IFERROR(INDEX(PitRawData!$A$1:$AMK$3,3,MATCH(I24,PitRawData!$A$1:$AMK$1,0)),"NO DATA") -> NO DATA | D24: =IFERROR(INDEX(PitRawData!$A$1:$AMK$3,3,MATCH(J24,PitRawData!$A$1:$AMK$1,0)),"NO DATA") -> NO DATA | E24: =IFERROR(INDEX(PitRawData!$A$1:$AMK$3,3,MATCH(K24,PitRawData!$A$1:$AMK$1,0)),"NO DATA") -> NO DATA | F24: =SUM(B24:E24) -> 0 | H24: personChildNativeHawaiianNHEmergency | I24: personChildNativeHawaiianNHTransitional | J24: personChildNativeHawaiianNHSafeHaven | K24: personChildNativeHawaiianNHUnsheltered
A25: Native Hawaiian or Pacific Islander & Hispanic/Latina/e/o | B25: =IFERROR(INDEX(PitRawData!$A$1:$AMK$3,3,MATCH(H25,PitRawData!$A$1:$AMK$1,0)),"NO DATA") -> NO DATA | C25: =IFERROR(INDEX(PitRawData!$A$1:$AMK$3,3,MATCH(I25,PitRawData!$A$1:$AMK$1,0)),"NO DATA") -> NO DATA | D25: =IFERROR(INDEX(PitRawData!$A$1:$AMK$3,3,MATCH(J25,PitRawData!$A$1:$AMK$1,0)),"NO DATA") -> NO DATA | E25: =IFERROR(INDEX(PitRawData!$A$1:$AMK$3,3,MATCH(K25,PitRawData!$A$1:$AMK$1,0)),"NO DATA") -> NO DATA | F25: =SUM(B25:E25) -> 0 | H25: personChildNativeHawaiianHEmergency | I25: personChildNativeHawaiianHTransitional | J25: personChildNativeHawaiianHSafeHaven | K25: personChildNativeHawaiianHUnsheltered
A26: White (only) | B26: =IFERROR(INDEX(PitRawData!$A$1:$AMK$3,3,MATCH(H26,PitRawData!$A$1:$AMK$1,0)),"NO DATA") -> NO DATA | C26: =IFERROR(INDEX(PitRawData!$A$1:$AMK$3,3,MATCH(I26,PitRawData!$A$1:$AMK$1,0)),"NO DATA") -> NO DATA | D26: =IFERROR(INDEX(PitRawData!$A$1:$AMK$3,3,MATCH(J26,PitRawData!$A$1:$AMK$1,0)),"NO DATA") -> NO DATA | E26: =IFERROR(INDEX(PitRawData!$A$1:$AMK$3,3,MATCH(K26,PitRawData!$A$1:$AMK$1,0)),"NO DATA") -> NO DATA | F26: =SUM(B26:E26) -> 0 | H26: personChildWhiteNHEmergency | I26: personChildWhiteNHTransitional | J26: personChildWhiteNHSafeHaven | K26: personChildWhiteNHUnsheltered
... A29: Multi-Racial (all other) | B29: =IFERROR(INDEX(PitRawData!$A$1:$AMK$3,3,MATCH(H29,PitRawData!$A$1:$AMK$1,0)),"NO DATA") -> NO DATA | C29: =IFERROR(INDEX(PitRawData!$A$1:$AMK$3,3,MATCH(I29,PitRawData!$A$1:$AMK$1,0)),"NO DATA") -> NO DATA | D29: =IFERROR(INDEX(PitRawData!$A$1:$AMK$3,3,MATCH(J29,PitRawData!$A$1:$AMK$1,0)),"NO DATA") -> NO DATA | E29: =IFERROR(INDEX(PitRawData!$A$1:$AMK$3,3,MATCH(K29,PitRawData!$A$1:$AMK$1,0)),"NO DATA") -> NO DATA | F29: =SUM(B29:E29) -> 0 | H29: personChildMultipleRaceNHEmergency | I29: personChildMultipleRaceNHTransitional | J29: personChildMultipleRaceNHSafeHaven | K29: personChildMultipleRaceNHUnsheltered
B31: Sheltered | E31: Unsheltered | F31: Total
A32: Chronically Homeless | B32: Emergency | C32: Transitional | D32: Safe Haven
A33: Total number of persons | B33: =IFERROR(INDEX(PitRawData!$A$1:$AMK$3,3,MATCH(H33,PitRawData!$A$1:$AMK$1,0)),"NO DATA") -> NO DATA | C33: N/A | D33: =IFERROR(INDEX(PitRawData!$A$1:$AMK$3,3,MATCH(J33,PitRawData!$A$1:$AMK$1,0)),"NO DATA") -> NO DATA | E33: =IFERROR(INDEX(PitRawData!$A$1:$AMK$3,3,MATCH(K33,PitRawData!$A$1:$AMK$1,0)),"NO DATA") -> NO DATA | F33: =SUM(B33:E33) -> 0 | H33: personChildCronPersonsEmergency | J33: personChildCronPersonsSafeHaven | K33: personChildCronPersonsUnsheltered

Sheet All_AO
A1: PIT Summary Report
A2: =HeadingLine2
A3: =HeadingLine3 -> PASTE DATA INTO THE 'PitRawData' TAB TO POPULATE THIS TEMPLATE.
A4: =HeadingLine4
A6: All Persons: Persons in Households wth Adults Only ("AO")
B8: Sheltered | E8: Unsheltered | F8: Total
A9: Persons and Households | B9: Emergency | C9: Transitional | D9: Safe Haven
A10: Total Number of Households | B10: =IFERROR(INDEX(PitRawData!$A$1:$AMK$3,3,MATCH(H10,PitRawData!$A$1:$AMK$1,0)),"NO DATA") -> NO DATA | C10: =IFERROR(INDEX(PitRawData!$A$1:$AMK$3,3,MATCH(I10,PitRawData!$A$1:$AMK$1,0)),"NO DATA") -> NO DATA | D10: =IFERROR(INDEX(PitRawData!$A$1:$AMK$3,3,MATCH(J10,PitRawData!$A$1:$AMK$1,0)),"NO DATA") -> NO DATA | E10: =IFERROR(INDEX(PitRawData!$A$1:$AMK$3,3,MATCH(K10,PitRawData!$A$1:$AMK$1,0)),"NO DATA") -> NO DATA | F10: =SUM(B10:E10) -> 0 | H10: householdAdultEmergency | I10: householdAdultTransitional | J10: householdAdultSafeHaven | K10: householdAdultUnsheltered
A11: Total Number of Persons (Adults) | B11: =SUM(B12:B17) -> 0 | C11: =SUM(C12:C17) -> 0 | D11: =SUM(D12:D17) -> 0 | E11: =SUM(E12:E17) -> 0 | F11: =SUM(B11:E11) -> 0
A12: Number of Persons (18 - 24) | B12: =IFERROR(INDEX(PitRawData!$A$1:$AMK$3,3,MATCH(H12,PitRawData!$A$1:$AMK$1,0)),"NO DATA") -> NO DATA | C12: =IFERROR(INDEX(PitRawData!$A$1:$AMK$3,3,MATCH(I12,PitRawData!$A$1:$AMK$1,0)),"NO DATA") -> NO DATA | D12: =IFERROR(INDEX(PitRawData!$A$1:$AMK$3,3,MATCH(J12,PitRawData!$A$1:$AMK$1,0)),"NO DATA") -> NO DATA | E12: =IFERROR(INDEX(PitRawData!$A$1:$AMK$3,3,MATCH(K12,PitRawData!$A$1:$AMK$1,0)),"NO DATA") -> NO DATA | F12: =SUM(B12:E12) -> 0 | H12: personAdult18To24Emergency | I12: personAdult18To24Transitional | J12: personAdult18To24SafeHaven | K12: personAdult18To24Unsheltered
A13: Number of Persons (25 - 34) | B13: =IFERROR(INDEX(PitRawData!$A$1:$AMK$3,3,MATCH(H13,PitRawData!$A$1:$AMK$1,0)),"NO DATA") -> NO DATA | C13: =IFERROR(INDEX(PitRawData!$A$1:$AMK$3,3,MATCH(I13,PitRawData!$A$1:$AMK$1,0)),"NO DATA") -> NO DATA | D13: =IFERROR(INDEX(PitRawData!$A$1:$AMK$3,3,MATCH(J13,PitRawData!$A$1:$AMK$1,0)),"NO DATA") -> NO DATA | E13: =IFERROR(INDEX(PitRawData!$A$1:$AMK$3,3,MATCH(K13,PitRawData!$A$1:$AMK$1,0)),"NO DATA") -> NO DATA | F13: =SUM(B13:E13) -> 0 | H13: personAdult25To34Emergency | I13: personAdult25To34Transitional | J13: personAdult25To34SafeHaven | K13: personAdult25To34Unsheltered
A14: Number of Persons (35 - 44) | B14: =IFERROR(INDEX(PitRawData!$A$1:$AMK$3,3,MATCH(H14,PitRawData!$A$1:$AMK$1,0)),"NO DATA") -> NO DATA | C14: =IFERROR(INDEX(PitRawData!$A$1:$AMK$3,3,MATCH(I14,PitRawData!$A$1:$AMK$1,0)),"NO DATA") -> NO DATA | D14: =IFERROR(INDEX(PitRawData!$A$1:$AMK$3,3,MATCH(J14,PitRawData!$A$1:$AMK$1,0)),"NO DATA") -> NO DATA | E14: =IFERROR(INDEX(PitRawData!$A$1:$AMK$3,3,MATCH(K14,PitRawData!$A$1:$AMK$1,0)),"NO DATA") -> NO DATA | F14: =SUM(B14:E14) -> 0 | H14: personAdult35To44Emergency | I14: personAdult35To44Transitional | J14: personAdult35To44SafeHaven | K14: personAdult35To44Unsheltered
A15: Number of Persons (45 - 54) | B15: =IFERROR(INDEX(PitRawData!$A$1:$AMK$3,3,MATCH(H15,PitRawData!$A$1:$AMK$1,0)),"NO DATA") -> NO DATA | C15: =IFERROR(INDEX(PitRawData!$A$1:$AMK$3,3,MATCH(I15,PitRawData!$A$1:$AMK$1,0)),"NO DATA") -> NO DATA | D15: =IFERROR(INDEX(PitRawData!$A$1:$AMK$3,3,MATCH(J15,PitRawData!$A$1:$AMK$1,0)),"NO DATA") -> NO DATA | E15: =IFERROR(INDEX(PitRawData!$A$1:$AMK$3,3,MATCH(K15,PitRawData!$A$1:$AMK$1,0)),"NO DATA") -> NO DATA | F15: =SUM(B15:E15) -> 0 | H15: personAdult45To54Emergency | I15: personAdult45To54Transitional | J15: personAdult45To54SafeHaven | K15: personAdult45To54Unsheltered
A16: Number of Persons (55 - 64) | B16: =IFERROR(INDEX(PitRawData!$A$1:$AMK$3,3,MATCH(H16,PitRawData!$A$1:$AMK$1,0)),"NO DATA") -> NO DATA | C16: =IFERROR(INDEX(PitRawData!$A$1:$AMK$3,3,MATCH(I16,PitRawData!$A$1:$AMK$1,0)),"NO DATA") -> NO DATA | D16: =IFERROR(INDEX(PitRawData!$A$1:$AMK$3,3,MATCH(J16,PitRawData!$A$1:$AMK$1,0)),"NO DATA") -> NO DATA | E16: =IFERROR(INDEX(PitRawData!$A$1:$AMK$3,3,MATCH(K16,PitRawData!$A$1:$AMK$1,0)),"NO DATA") -> NO DATA | F16: =SUM(B16:E16) -> 0 | H16: personAdult55To64Emergency | I16: personAdult55To64Transitional | J16: personAdult55To64SafeHaven | K16: personAdult55To64Unsheltered
A17: Number of Persons (over 64) | B17: =IFERROR(INDEX(PitRawData!$A$1:$AMK$3,3,MATCH(H17,PitRawData!$A$1:$AMK$1,0)),"NO DATA") -> NO DATA | C17: =IFERROR(INDEX(PitRawData!$A$1:$AMK$3,3,MATCH(I17,PitRawData!$A$1:$AMK$1,0)),"NO DATA") -> NO DATA | D17: =IFERROR(INDEX(PitRawData!$A$1:$AMK$3,3,MATCH(J17,PitRawData!$A$1:$AMK$1,0)),"NO DATA") -> NO DATA | E17: =IFERROR(INDEX(PitRawData!$A$1:$AMK$3,3,MATCH(K17,PitRawData!$A$1:$AMK$1,0)),"NO DATA") -> NO DATA | F17: =SUM(B17:E17) -> 0 | H17: personAdultOver64Emergency | I17: personAdultOver64Transitional | J17: personAdultOver64SafeHaven | K17: personAdultOver64Unsheltered
B19: Sheltered | E19: Unsheltered | F19: Total
A20: Race/Ethnicity | B20: Emergency | C20: Transitional | D20: Safe Haven
A21: American Indian, Alaska Native, or Indigenous (only) | B21: =IFERROR(INDEX(PitRawData!$A$1:$AMK$3,3,MATCH(H21,PitRawData!$A$1:$AMK$1,0)),"NO DATA") -> NO DATA | C21: =IFERROR(INDEX(PitRawData!$A$1:$AMK$3,3,MATCH(I21,PitRawData!$A$1:$AMK$1,0)),"NO DATA") -> NO DATA | D21: =IFERROR(INDEX(PitRawData!$A$1:$AMK$3,3,MATCH(J21,PitRawData!$A$1:$AMK$1,0)),"NO DATA") -> NO DATA | E21: =IFERROR(INDEX(PitRawData!$A$1:$AMK$3,3,MATCH(K21,PitRawData!$A$1:$AMK$1,0)),"NO DATA") -> NO DATA | F21: =SUM(B21:E21) -> 0 | H21: personAdultAmericanIndianNHEmergency | I21: personAdultAmericanIndianNHTransitional | J21: personAdultAmericanIndianNHSafeHaven | K21: personAdultAmericanIndianNHUnsheltered
A22: American Indian, Alaska Native, or Indigenous & Hispanic/Latina/e/o | B22: =IFERROR(INDEX(PitRawData!$A$1:$AMK$3,3,MATCH(H22,PitRawData!$A$1:$AMK$1,0)),"NO DATA") -> NO DATA | C22: =IFERROR(INDEX(PitRawData!$A$1:$AMK$3,3,MATCH(I22,PitRawData!$A$1:$AMK$1,0)),"NO DATA") -> NO DATA | D22: =IFERROR(INDEX(PitRawData!$A$1:$AMK$3,3,MATCH(J22,PitRawData!$A$1:$AMK$1,0)),"NO DATA") -> NO DATA | E22: =IFERROR(INDEX(PitRawData!$A$1:$AMK$3,3,MATCH(K22,PitRawData!$A$1:$AMK$1,0)),"NO DATA") -> NO DATA | F22: =SUM(B22:E22) -> 0 | H22: personAdultAmericanIndianHEmergency | I22: personAdultAmericanIndianHTransitional | J22: personAdultAmericanIndianHSafeHaven | K22: personAdultAmericanIndianHUnsheltered
A23: Asian or Asian American (only) | B23: =IFERROR(INDEX(PitRawData!$A$1:$AMK$3,3,MATCH(H23,PitRawData!$A$1:$AMK$1,0)),"NO DATA") -> NO DATA | C23: =IFERROR(INDEX(PitRawData!$A$1:$AMK$3,3,MATCH(I23,PitRawData!$A$1:$AMK$1,0)),"NO DATA") -> NO DATA | D23: =IFERROR(INDEX(PitRawData!$A$1:$AMK$3,3,MATCH(J23,PitRawData!$A$1:$AMK$1,0)),"NO DATA") -> NO DATA | E23: =IFERROR(INDEX(PitRawData!$A$1:$AMK$3,3,MATCH(K23,PitRawData!$A$1:$AMK$1,0)),"NO DATA") -> NO DATA | F23: =SUM(B23:E23) -> 0 | H23: personAdultAsianNHEmergency | I23: personAdultAsianNHTransitional | J23: personAdultAsianNHSafeHaven | K23: personAdultAsianNHUnsheltered
A24: Asian or Asian American & Hispanic/Latina/e/o | B24: =IFERROR(INDEX(PitRawData!$A$1:$AMK$3,3,MATCH(H24,PitRawData!$A$1:$AMK$1,0)),"NO DATA") -> NO DATA | C24: =IFERROR(INDEX(PitRawData!$A$1:$AMK$3,3,MATCH(I24,PitRawData!$A$1:$AMK$1,0)),"NO DATA") -> NO DATA | D24: =IFERROR(INDEX(PitRawData!$A$1:$AMK$3,3,MATCH(J24,PitRawData!$A$1:$AMK$1,0)),"NO DATA") -> NO DATA | E24: =IFERROR(INDEX(PitRawData!$A$1:$AMK$3,3,MATCH(K24,PitRawData!$A$1:$AMK$1,0)),"NO DATA") -> NO DATA | F24: =SUM(B24:E24) -> 0 | H24: personAdultAsianHEmergency | I24: personAdultAsianHTransitional | J24: personAdultAsianHSafeHaven | K24: personAdultAsianHUnsheltered
A25: Black, African American, or African (only) | B25: =IFERROR(INDEX(PitRawData!$A$1:$AMK$3,3,MATCH(H25,PitRawData!$A$1:$AMK$1,0)),"NO DATA") -> NO DATA | C25: =IFERROR(INDEX(PitRawData!$A$1:$AMK$3,3,MATCH(I25,PitRawData!$A$1:$AMK$1,0)),"NO DATA") -> NO DATA | D25: =IFERROR(INDEX(PitRawData!$A$1:$AMK$3,3,MATCH(J25,PitRawData!$A$1:$AMK$1,0)),"NO DATA") -> NO DATA | E25: =IFERROR(INDEX(PitRawData!$A$1:$AMK$3,3,MATCH(K25,PitRawData!$A$1:$AMK$1,0)),"NO DATA") -> NO DATA | F25: =SUM(B25:E25) -> 0 | H25: personAdultBlackNHEmergency | I25: personAdultBlackNHTransitional | J25: personAdultBlackNHSafeHaven | K25: personAdultBlackNHUnsheltered
A26: Black, African American, or African & Hispanic/Latina/e/o | B26: =IFERROR(INDEX(PitRawData!$A$1:$AMK$3,3,MATCH(H26,PitRawData!$A$1:$AMK$1,0)),"NO DATA") -> NO DATA | C26: =IFERROR(INDEX(PitRawData!$A$1:$AMK$3,3,MATCH(I26,PitRawData!$A$1:$AMK$1,0)),"NO DATA") -> NO DATA | D26: =IFERROR(INDEX(PitRawData!$A$1:$AMK$3,3,MATCH(J26,PitRawData!$A$1:$AMK$1,0)),"NO DATA") -> NO DATA | E26: =IFERROR(INDEX(PitRawData!$A$1:$AMK$3,3,MATCH(K26,PitRawData!$A$1:$AMK$1,0)),"NO DATA") -> NO DATA | F26: =SUM(B26:E26) -> 0 | H26: personAdultBlackHEmergency | I26: personAdultBlackHTransitional | J26: personAdultBlackHSafeHaven | K26: personAdultBlackHUnsheltered
A27: Hispanic/Latina/e/o (only) | B27: =IFERROR(INDEX(PitRawData!$A$1:$AMK$3,3,MATCH(H27,PitRawData!$A$1:$AMK$1,0)),"NO DATA") -> NO DATA | C27: =IFERROR(INDEX(PitRawData!$A$1:$AMK$3,3,MATCH(I27,PitRawData!$A$1:$AMK$1,0)),"NO DATA") -> NO DATA | D27: =IFERROR(INDEX(PitRawData!$A$1:$AMK$3,3,MATCH(J27,PitRawData!$A$1:$AMK$1,0)),"NO DATA") -> NO DATA | E27: =IFERROR(INDEX(PitRawData!$A$1:$AMK$3,3,MATCH(K27,PitRawData!$A$1:$AMK$1,0)),"NO DATA") -> NO DATA | F27: =SUM(B27:E27) -> 0 | H27: personAdultHispanicEmergency | I27: personAdultHispanicTransitional | J27: personAdultHispanicSafeHaven | K27: personAdultHispanicUnsheltered
A28: Middle Eastern or North African (only) | B28: =IFERROR(INDEX(PitRawData!$A$1:$AMK$3,3,MATCH(H28,PitRawData!$A$1:$AMK$1,0)),"NO DATA") -> NO DATA | C28: =IFERROR(INDEX(PitRawData!$A$1:$AMK$3,3,MATCH(I28,PitRawData!$A$1:$AMK$1,0)),"NO DATA") -> NO DATA | D28: =IFERROR(INDEX(PitRawData!$A$1:$AMK$3,3,MATCH(J28,PitRawData!$A$1:$AMK$1,0)),"NO DATA") -> NO DATA | E28: =IFERROR(INDEX(PitRawData!$A$1:$AMK$3,3,MATCH(K28,PitRawData!$A$1:$AMK$1,0)),"NO DATA") -> NO DATA | F28: =SUM(B28:E28) -> 0 | H28: personAdultMENANHEmergency | I28: personAdultMENANHTransitional | J28: personAdultMENANHSafeHaven | K28: personAdultMENANHUnsheltered
A29: Middle Eastern or North African & Hispanic/Latina/e/o | B29: =IFERROR(INDEX(PitRawData!$A$1:$AMK$3,3,MATCH(H29,PitRawData!$A$1:$AMK$1,0)),"NO DATA") -> NO DATA | C29: =IFERROR(INDEX(PitRawData!$A$1:$AMK$3,3,MATCH(I29,PitRawData!$A$1:$AMK$1,0)),"NO DATA") -> NO DATA | D29: =IFERROR(INDEX(PitRawData!$A$1:$AMK$3,3,MATCH(J29,PitRawData!$A$1:$AMK$1,0)),"NO DATA") -> NO DATA | E29: =IFERROR(INDEX(PitRawData!$A$1:$AMK$3,3,MATCH(K29,PitRawData!$A$1:$AMK$1,0)),"NO DATA") -> NO DATA | F29: =SUM(B29:E29) -> 0 | H29: personAdultMENAHEmergency | I29: personAdultMENAHTransitional | J29: personAdultMENAHSafeHaven | K29: personAdultMENAHUnsheltered
A30: Native Hawaiian or Pacific Islander (only) | B30: =IFERROR(INDEX(PitRawData!$A$1:$AMK$3,3,MATCH(H30,PitRawData!$A$1:$AMK$1,0)),"NO DATA") -> NO DATA | C30: =IFERROR(INDEX(PitRawData!$A$1:$AMK$3,3,MATCH(I30,PitRawData!$A$1:$AMK$1,0)),"NO DATA") -> NO DATA | D30: =IFERROR(INDEX(PitRawData!$A$1:$AMK$3,3,MATCH(J30,PitRawData!$A$1:$AMK$1,0)),"NO DATA") -> NO DATA | E30: =IFERROR(INDEX(PitRawData!$A$1:$AMK$3,3,MATCH(K30,PitRawData!$A$1:$AMK$1,0)),"NO DATA") -> NO DATA | F30: =SUM(B30:E30) -> 0 | H30: personAdultNativeHawaiianNHEmergency | I30: personAdultNativeHawaiianNHTransitional | J30: personAdultNativeHawaiianNHSafeHaven | K30: personAdultNativeHawaiianNHUnsheltered
A31: Native Hawaiian or Pacific Islander & Hispanic/Latina/e/o | B31: =IFERROR(INDEX(PitRawData!$A$1:$AMK$3,3,MATCH(H31,PitRawData!$A$1:$AMK$1,0)),"NO DATA") -> NO DATA | C31: =IFERROR(INDEX(PitRawData!$A$1:$AMK$3,3,MATCH(I31,PitRawData!$A$1:$AMK$1,0)),"NO DATA") -> NO DATA | D31: =IFERROR(INDEX(PitRawData!$A$1:$AMK$3,3,MATCH(J31,PitRawData!$A$1:$AMK$1,0)),"NO DATA") -> NO DATA | E31: =IFERROR(INDEX(PitRawData!$A$1:$AMK$3,3,MATCH(K31,PitRawData!$A$1:$AMK$1,0)),"NO DATA") -> NO DATA | F31: =SUM(B31:E31) -> 0 | H31: personAdultNativeHawaiianHEmergency | I31: personAdultNativeHawaiianHTransitional | J31: personAdultNativeHawaiianHSafeHaven | K31: personAdultNativeHawaiianHUnsheltered
A32: White (only) | B32: =IFERROR(INDEX(PitRawData!$A$1:$AMK$3,3,MATCH(H32,PitRawData!$A$1:$AMK$1,0)),"NO DATA") -> NO DATA | C32: =IFERROR(INDEX(PitRawData!$A$1:$AMK$3,3,MATCH(I32,PitRawData!$A$1:$AMK$1,0)),"NO DATA") -> NO DATA | D32: =IFERROR(INDEX(PitRawData!$A$1:$AMK$3,3,MATCH(J32,PitRawData!$A$1:$AMK$1,0)),"NO DATA") -> NO DATA | E32: =IFERROR(INDEX(PitRawData!$A$1:$AMK$3,3,MATCH(K32,PitRawData!$A$1:$AMK$1,0)),"NO DATA") -> NO DATA | F32: =SUM(B32:E32) -> 0 | H32: personAdultWhiteNHEmergency | I32: personAdultWhiteNHTransitional | J32: personAdultWhiteNHSafeHaven | K32: personAdultWhiteNHUnsheltered
... A35: Multi-Racial (all other) | B35: =IFERROR(INDEX(PitRawData!$A$1:$AMK$3,3,MATCH(H35,PitRawData!$A$1:$AMK$1,0)),"NO DATA") -> NO DATA | C35: =IFERROR(INDEX(PitRawData!$A$1:$AMK$3,3,MATCH(I35,PitRawData!$A$1:$AMK$1,0)),"NO DATA") -> NO DATA | D35: =IFERROR(INDEX(PitRawData!$A$1:$AMK$3,3,MATCH(J35,PitRawData!$A$1:$AMK$1,0)),"NO DATA") -> NO DATA | E35: =IFERROR(INDEX(PitRawData!$A$1:$AMK$3,3,MATCH(K35,PitRawData!$A$1:$AMK$1,0)),"NO DATA") -> NO DATA | F35: =SUM(B35:E35) -> 0 | H35: personAdultMultipleRaceNHEmergency | I35: personAdultMultipleRaceNHTransitional | J35: personAdultMultipleRaceNHSafeHaven | K35: personAdultMultipleRaceNHUnsheltered
B37: Sheltered | E37: Unsheltered | F37: Total
A38: Chronically Homeless | B38: Emergency | C38: Transitional | D38: Safe Haven
A39: Total number of persons | B39: =IFERROR(INDEX(PitRawData!$A$1:$AMK$3,3,MATCH(H39,PitRawData!$A$1:$AMK$1,0)),"NO DATA") -> NO DATA | C39: N/A | D39: =IFERROR(INDEX(PitRawData!$A$1:$AMK$3,3,MATCH(J39,PitRawData!$A$1:$AMK$1,0)),"NO DATA") -> NO DATA | E39: =IFERROR(INDEX(PitRawData!$A$1:$AMK$3,3,MATCH(K39,PitRawData!$A$1:$AMK$1,0)),"NO DATA") -> NO DATA | F39: =SUM(B39:E39) -> 0 | H39: personAdultCronPersonsEmergency | J39: personAdultCronPersonsSafeHaven | K39: personAdultCronPersonsUnsheltered

Sheet All_TOTALS
A1: PIT Summary Report
A2: =HeadingLine2
A3: =HeadingLine3 -> PASTE DATA INTO THE 'PitRawData' TAB TO POPULATE THIS TEMPLATE.
A4: =HeadingLine4
A6: All Persons, TOTALS
B8: Sheltered | E8: Unsheltered | F8: Total
A9: Persons and Households | B9: Emergency | C9: Transitional | D9: Safe Haven
A10: Total Number of Households | B10: =All_AC!B10+All_CO!B10+All_AO!B10 -> #VALUE! | C10: =All_AC!C10+All_CO!C10+All_AO!C10 -> #VALUE! | D10: =All_CO!D10+All_AO!D10 -> #VALUE! | E10: =All_AC!D10+All_CO!E10+All_AO!E10 -> #VALUE! | F10: =SUM(B10:E10) -> #VALUE!
A11: Total Number of Persons (Adults & Children) | B11: =SUM(B12:B18) -> #VALUE! | C11: =SUM(C12:C18) -> #VALUE! | D11: =SUM(D12:D18) -> 0 | E11: =SUM(E12:E18) -> #VALUE! | F11: =SUM(B11:E11) -> #VALUE!
A12: Number of Persons (under 18) | B12: =All_AC!B12+All_CO!B11 -> #VALUE! | C12: =All_AC!C12+All_CO!C11 -> #VALUE! | D12: =All_CO!D11 -> NO DATA | E12: =All_AC!D12+All_CO!E11 -> #VALUE! | F12: =SUM(B12:E12) -> #VALUE!
A13: Number of Persons (18 - 24) | B13: =All_AC!B13+All_AO!B12 -> #VALUE! | C13: =All_AC!C13+All_AO!C12 -> #VALUE! | D13: =All_AO!D12 -> NO DATA | E13: =All_AC!D13+All_AO!E12 -> #VALUE! | F13: =SUM(B13:E13) -> #VALUE!
A14: Number of Persons (25 - 34) | B14: =All_AC!B14+All_AO!B13 -> #VALUE! | C14: =All_AC!C14+All_AO!C13 -> #VALUE! | D14: =All_AO!D13 -> NO DATA | E14: =All_AC!D14+All_AO!E13 -> #VALUE! | F14: =SUM(B14:E14) -> #VALUE!
A15: Number of Persons (35 - 44) | B15: =All_AC!B15+All_AO!B14 -> #VALUE! | C15: =All_AC!C15+All_AO!C14 -> #VALUE! | D15: =All_AO!D14 -> NO DATA | E15: =All_AC!D15+All_AO!E14 -> #VALUE! | F15: =SUM(B15:E15) -> #VALUE!
A16: Number of Persons (45 - 54) | B16: =All_AC!B16+All_AO!B15 -> #VALUE! | C16: =All_AC!C16+All_AO!C15 -> #VALUE! | D16: =All_AO!D15 -> NO DATA | E16: =All_AC!D16+All_AO!E15 -> #VALUE! | F16: =SUM(B16:E16) -> #VALUE!
A17: Number of Persons (55 - 64) | B17: =All_AC!B17+All_AO!B16 -> #VALUE! | C17: =All_AC!C17+All_AO!C16 -> #VALUE! | D17: =All_AO!D16 -> NO DATA | E17: =All_AC!D17+All_AO!E16 -> #VALUE! | F17: =SUM(B17:E17) -> #VALUE!
A18: Number of Persons (over 64) | B18: =All_AC!B18+All_AO!B17 -> #VALUE! | C18: =All_AC!C18+All_AO!C17 -> #VALUE! | D18: =All_AO!D17 -> NO DATA | E18: =All_AC!D18+All_AO!E17 -> #VALUE! | F18: =SUM(B18:E18) -> #VALUE!
B20: Sheltered | E20: Unsheltered | F20: Total
A21: Race/Ethnicity (Adults and Children) | B21: Emergency | C21: Transitional | D21: Safe Haven
A22: American Indian, Alaska Native, or Indigenous (only) | B22: =All_AC!B22+All_CO!B15+All_AO!B21 -> #VALUE! | C22: =All_AC!C22+All_CO!C15+All_AO!C21 -> #VALUE! | D22: =All_CO!D15+All_AO!D21 -> #VALUE! | E22: =All_AC!D22+All_CO!E15+All_AO!E21 -> #VALUE! | F22: =SUM(B22:E22) -> #VALUE!
A23: American Indian, Alaska Native, or Indigenous & Hispanic/Latina/e/o | B23: =All_AC!B23+All_CO!B16+All_AO!B22 -> #VALUE! | C23: =All_AC!C23+All_CO!C16+All_AO!C22 -> #VALUE! | D23: =All_CO!D16+All_AO!D22 -> #VALUE! | E23: =All_AC!D23+All_CO!E16+All_AO!E22 -> #VALUE! | F23: =SUM(B23:E23) -> #VALUE!
A24: Asian or Asian American (only) | B24: =All_AC!B24+All_CO!B17+All_AO!B23 -> #VALUE! | C24: =All_AC!C24+All_CO!C17+All_AO!C23 -> #VALUE! | D24: =All_CO!D17+All_AO!D23 -> #VALUE! | E24: =All_AC!D24+All_CO!E17+All_AO!E23 -> #VALUE! | F24: =SUM(B24:E24) -> #VALUE!
A25: Asian or Asian American & Hispanic/Latina/e/o | B25: =All_AC!B25+All_CO!B18+All_AO!B24 -> #VALUE! | C25: =All_AC!C25+All_CO!C18+All_AO!C24 -> #VALUE! | D25: =All_CO!D18+All_AO!D24 -> #VALUE! | E25: =All_AC!D25+All_CO!E18+All_AO!E24 -> #VALUE! | F25: =SUM(B25:E25) -> #VALUE!
A26: Black, African American, or African (only) | B26: =All_AC!B26+All_CO!B19+All_AO!B25 -> #VALUE! | C26: =All_AC!C26+All_CO!C19+All_AO!C25 -> #VALUE! | D26: =All_CO!D19+All_AO!D25 -> #VALUE! | E26: =All_AC!D26+All_CO!E19+All_AO!E25 -> #VALUE! | F26: =SUM(B26:E26) -> #VALUE!
A27: Black, African American, or African & Hispanic/Latina/e/o | B27: =All_AC!B27+All_CO!B20+All_AO!B26 -> #VALUE! | C27: =All_AC!C27+All_CO!C20+All_AO!C26 -> #VALUE! | D27: =All_CO!D20+All_AO!D26 -> #VALUE! | E27: =All_AC!D27+All_CO!E20+All_AO!E26 -> #VALUE! | F27: =SUM(B27:E27) -> #VALUE!
A28: Hispanic/Latina/e/o (only) | B28: =All_AC!B28+All_CO!B21+All_AO!B27 -> #VALUE! | C28: =All_AC!C28+All_CO!C21+All_AO!C27 -> #VALUE! | D28: =All_CO!D21+All_AO!D27 -> #VALUE! | E28: =All_AC!D28+All_CO!E21+All_AO!E27 -> #VALUE! | F28: =SUM(B28:E28) -> #VALUE!
A29: Middle Eastern or North African (only) | B29: =All_AC!B29+All_CO!B22+All_AO!B28 -> #VALUE! | C29: =All_AC!C29+All_CO!C22+All_AO!C28 -> #VALUE! | D29: =All_CO!D22+All_AO!D28 -> #VALUE! | E29: =All_AC!D29+All_CO!E22+All_AO!E28 -> #VALUE! | F29: =SUM(B29:E29) -> #VALUE!
A30: Middle Eastern or North African & Hispanic/Latina/e/o | B30: =All_AC!B30+All_CO!B23+All_AO!B29 -> #VALUE! | C30: =All_AC!C30+All_CO!C23+All_AO!C29 -> #VALUE! | D30: =All_CO!D23+All_AO!D29 -> #VALUE! | E30: =All_AC!D30+All_CO!E23+All_AO!E29 -> #VALUE! | F30: =SUM(B30:E30) -> #VALUE!
A31: Native Hawaiian or Pacific Islander (only) | B31: =All_AC!B31+All_CO!B24+All_AO!B30 -> #VALUE! | C31: =All_AC!C31+All_CO!C24+All_AO!C30 -> #VALUE! | D31: =All_CO!D24+All_AO!D30 -> #VALUE! | E31: =All_AC!D31+All_CO!E24+All_AO!E30 -> #VALUE! | F31: =SUM(B31:E31) -> #VALUE!
A32: Native Hawaiian or Pacific Islander & Hispanic/Latina/e/o | B32: =All_AC!B32+All_CO!B25+All_AO!B31 -> #VALUE! | C32: =All_AC!C32+All_CO!C25+All_AO!C31 -> #VALUE! | D32: =All_CO!D25+All_AO!D31 -> #VALUE! | E32: =All_AC!D32+All_CO!E25+All_AO!E31 -> #VALUE! | F32: =SUM(B32:E32) -> #VALUE!
A33: White (only) | B33: =All_AC!B33+All_CO!B26+All_AO!B32 -> #VALUE! | C33: =All_AC!C33+All_CO!C26+All_AO!C32 -> #VALUE! | D33: =All_CO!D26+All_AO!D32 -> #VALUE! | E33: =All_AC!D33+All_CO!E26+All_AO!E32 -> #VALUE! | F33: =SUM(B33:E33) -> #VALUE!
... A36: Multi-Racial (all other) | B36: =All_AC!B36+All_CO!B29+All_AO!B35 -> #VALUE! | C36: =All_AC!C36+All_CO!C29+All_AO!C35 -> #VALUE! | D36: =All_CO!D29+All_AO!D35 -> #VALUE! | E36: =All_AC!D36+All_CO!E29+All_AO!E35 -> #VALUE! | F36: =SUM(B36:E36) -> #VALUE!
B38: Sheltered | E38: Unsheltered | F38: Total
A39: Chronically Homeless | B39: Emergency | C39: Transitional | D39: Safe Haven
A40: Total number of persons | B40: =All_AC!B41+All_CO!B33+All_AO!B39 -> #VALUE! | C40: N/A | D40: =All_CO!D33+All_AO!D39 -> #VALUE! | E40: =All_AC!D41+All_CO!E33+All_AO!E39 -> #VALUE! | F40: =SUM(B40:E40) -> #VALUE!

Sheet Youth_UY
A1: PIT Summary Report
A2: =HeadingLine2
A3: =HeadingLine3 -> PASTE DATA INTO THE 'PitRawData' TAB TO POPULATE THIS TEMPLATE.
A4: =HeadingLine4
A6: Youth Subpopulation: Unaccompanied Youth Households ("Youth UY")
B8: Sheltered | E8: Unsheltered | F8: Total
A9: Persons and Households | B9: Emergency | C9: Transitional | D9: Safe Haven
A10: Total Number of unaccompanied youth households | B10: =IFERROR(INDEX(PitRawData!$A$1:$AMK$3,3,MATCH(H10,PitRawData!$A$1:$AMK$1,0)),"NO DATA") -> NO DATA | C10: =IFERROR(INDEX(PitRawData!$A$1:$AMK$3,3,MATCH(I10,PitRawData!$A$1:$AMK$1,0)),"NO DATA") -> NO DATA | D10: =IFERROR(INDEX(PitRawData!$A$1:$AMK$3,3,MATCH(J10,PitRawData!$A$1:$AMK$1,0)),"NO DATA") -> NO DATA | E10: =IFERROR(INDEX(PitRawData!$A$1:$AMK$3,3,MATCH(K10,PitRawData!$A$1:$AMK$1,0)),"NO DATA") -> NO DATA | F10: =SUM(B10:E10) -> 0 | H10: householdUnaccompaniedYouthEmergency | I10: householdUnaccompaniedYouthTransitional | J10: householdUnaccompaniedYouthSafeHaven | K10: householdUnaccompaniedYouthUnsheltered
A11: Total number of unaccompanied youth | B11: =SUM(B12:B13) -> 0 | C11: =SUM(C12:C13) -> 0 | D11: =SUM(D12:D13) -> 0 | E11: =SUM(E12:E13) -> 0 | F11: =SUM(B11:E11) -> 0
A12: Number of unaccompanied children (under 18) | B12: =IFERROR(INDEX(PitRawData!$A$1:$AMK$3,3,MATCH(H12,PitRawData!$A$1:$AMK$1,0)),"NO DATA") -> NO DATA | C12: =IFERROR(INDEX(PitRawData!$A$1:$AMK$3,3,MATCH(I12,PitRawData!$A$1:$AMK$1,0)),"NO DATA") -> NO DATA | D12: =IFERROR(INDEX(PitRawData!$A$1:$AMK$3,3,MATCH(J12,PitRawData!$A$1:$AMK$1,0)),"NO DATA") -> NO DATA | E12: =IFERROR(INDEX(PitRawData!$A$1:$AMK$3,3,MATCH(K12,PitRawData!$A$1:$AMK$1,0)),"NO DATA") -> NO DATA | F12: =SUM(B12:E12) -> 0 | H12: personYouthUnaccompaniedUnder18Emergency | I12: personYouthUnaccompaniedUnder18Transitional | J12: personYouthUnaccompaniedUnder18SafeHaven | K12: personYouthUnaccompaniedUnder18Unsheltered
A13: Number of unaccompanied youth (18 - 24) | B13: =IFERROR(INDEX(PitRawData!$A$1:$AMK$3,3,MATCH(H13,PitRawData!$A$1:$AMK$1,0)),"NO DATA") -> NO DATA | C13: =IFERROR(INDEX(PitRawData!$A$1:$AMK$3,3,MATCH(I13,PitRawData!$A$1:$AMK$1,0)),"NO DATA") -> NO DATA | D13: =IFERROR(INDEX(PitRawData!$A$1:$AMK$3,3,MATCH(J13,PitRawData!$A$1:$AMK$1,0)),"NO DATA") -> NO DATA | E13: =IFERROR(INDEX(PitRawData!$A$1:$AMK$3,3,MATCH(K13,PitRawData!$A$1:$AMK$1,0)),"NO DATA") -> NO DATA | F13: =SUM(B13:E13) -> 0 | H13: personYouthUnaccompanied18To24Emergency | I13: personYouthUnaccompanied18To24Transitional | J13: personYouthUnaccompanied18To24SafeHaven | K13: personYouthUnaccompanied18To24Unsheltered
B15: Sheltered | E15: Unsheltered | F15: Total
A16: Race/Ethnicity | B16: Emergency | C16: Transitional | D16: Safe Haven
A17: American Indian, Alaska Native, or Indigenous (only) | B17: =IFERROR(INDEX(PitRawData!$A$1:$AMK$3,3,MATCH(H17,PitRawData!$A$1:$AMK$1,0)),"NO DATA") -> NO DATA | C17: =IFERROR(INDEX(PitRawData!$A$1:$AMK$3,3,MATCH(I17,PitRawData!$A$1:$AMK$1,0)),"NO DATA") -> NO DATA | D17: =IFERROR(INDEX(PitRawData!$A$1:$AMK$3,3,MATCH(J17,PitRawData!$A$1:$AMK$1,0)),"NO DATA") -> NO DATA | E17: =IFERROR(INDEX(PitRawData!$A$1:$AMK$3,3,MATCH(K17,PitRawData!$A$1:$AMK$1,0)),"NO DATA") -> NO DATA | F17: =SUM(B17:E17) -> 0 | H17: personYouthAmericanIndianNHEmergency | I17: personYouthAmericanIndianNHTransitional | J17: personYouthAmericanIndianNHSafeHaven | K17: personYouthAmericanIndianNHUnsheltered
A18: American Indian, Alaska Native, or Indigenous & Hispanic/Latina/e/o | B18: =IFERROR(INDEX(PitRawData!$A$1:$AMK$3,3,MATCH(H18,PitRawData!$A$1:$AMK$1,0)),"NO DATA") -> NO DATA | C18: =IFERROR(INDEX(PitRawData!$A$1:$AMK$3,3,MATCH(I18,PitRawData!$A$1:$AMK$1,0)),"NO DATA") -> NO DATA | D18: =IFERROR(INDEX(PitRawData!$A$1:$AMK$3,3,MATCH(J18,PitRawData!$A$1:$AMK$1,0)),"NO DATA") -> NO DATA | E18: =IFERROR(INDEX(PitRawData!$A$1:$AMK$3,3,MATCH(K18,PitRawData!$A$1:$AMK$1,0)),"NO DATA") -> NO DATA | F18: =SUM(B18:E18) -> 0 | H18: personYouthAmericanIndianHEmergency | I18: personYouthAmericanIndianHTransitional | J18: personYouthAmericanIndianHSafeHaven | K18: personYouthAmericanIndianHUnsheltered
A19: Asian or Asian American (only) | B19: =IFERROR(INDEX(PitRawData!$A$1:$AMK$3,3,MATCH(H19,PitRawData!$A$1:$AMK$1,0)),"NO DATA") -> NO DATA | C19: =IFERROR(INDEX(PitRawData!$A$1:$AMK$3,3,MATCH(I19,PitRawData!$A$1:$AMK$1,0)),"NO DATA") -> NO DATA | D19: =IFERROR(INDEX(PitRawData!$A$1:$AMK$3,3,MATCH(J19,PitRawData!$A$1:$AMK$1,0)),"NO DATA") -> NO DATA | E19: =IFERROR(INDEX(PitRawData!$A$1:$AMK$3,3,MATCH(K19,PitRawData!$A$1:$AMK$1,0)),"NO DATA") -> NO DATA | F19: =SUM(B19:E19) -> 0 | H19: personYouthAsianNHEmergency | I19: personYouthAsianNHTransitional | J19: personYouthAsianNHSafeHaven | K19: personYouthAsianNHUnsheltered
A20: Asian or Asian American & Hispanic/Latina/e/o | B20: =IFERROR(INDEX(PitRawData!$A$1:$AMK$3,3,MATCH(H20,PitRawData!$A$1:$AMK$1,0)),"NO DATA") -> NO DATA | C20: =IFERROR(INDEX(PitRawData!$A$1:$AMK$3,3,MATCH(I20,PitRawData!$A$1:$AMK$1,0)),"NO DATA") -> NO DATA | D20: =IFERROR(INDEX(PitRawData!$A$1:$AMK$3,3,MATCH(J20,PitRawData!$A$1:$AMK$1,0)),"NO DATA") -> NO DATA | E20: =IFERROR(INDEX(PitRawData!$A$1:$AMK$3,3,MATCH(K20,PitRawData!$A$1:$AMK$1,0)),"NO DATA") -> NO DATA | F20: =SUM(B20:E20) -> 0 | H20: personYouthAsianHEmergency | I20: personYouthAsianHTransitional | J20: personYouthAsianHSafeHaven | K20: personYouthAsianHUnsheltered
A21: Black, African American, or African (only) | B21: =IFERROR(INDEX(PitRawData!$A$1:$AMK$3,3,MATCH(H21,PitRawData!$A$1:$AMK$1,0)),"NO DATA") -> NO DATA | C21: =IFERROR(INDEX(PitRawData!$A$1:$AMK$3,3,MATCH(I21,PitRawData!$A$1:$AMK$1,0)),"NO DATA") -> NO DATA | D21: =IFERROR(INDEX(PitRawData!$A$1:$AMK$3,3,MATCH(J21,PitRawData!$A$1:$AMK$1,0)),"NO DATA") -> NO DATA | E21: =IFERROR(INDEX(PitRawData!$A$1:$AMK$3,3,MATCH(K21,PitRawData!$A$1:$AMK$1,0)),"NO DATA") -> NO DATA | F21: =SUM(B21:E21) -> 0 | H21: personYouthBlackNHEmergency | I21: personYouthBlackNHTransitional | J21: personYouthBlackNHSafeHaven | K21: personYouthBlackNHUnsheltered
A22: Black, African American, or African & Hispanic/Latina/e/o | B22: =IFERROR(INDEX(PitRawData!$A$1:$AMK$3,3,MATCH(H22,PitRawData!$A$1:$AMK$1,0)),"NO DATA") -> NO DATA | C22: =IFERROR(INDEX(PitRawData!$A$1:$AMK$3,3,MATCH(I22,PitRawData!$A$1:$AMK$1,0)),"NO DATA") -> NO DATA | D22: =IFERROR(INDEX(PitRawData!$A$1:$AMK$3,3,MATCH(J22,PitRawData!$A$1:$AMK$1,0)),"NO DATA") -> NO DATA | E22: =IFERROR(INDEX(PitRawData!$A$1:$AMK$3,3,MATCH(K22,PitRawData!$A$1:$AMK$1,0)),"NO DATA") -> NO DATA | F22: =SUM(B22:E22) -> 0 | H22: personYouthBlackHEmergency | I22: personYouthBlackHTransitional | J22: personYouthBlackHSafeHaven | K22: personYouthBlackHUnsheltered
A23: Hispanic/Latina/e/o (only) | B23: =IFERROR(INDEX(PitRawData!$A$1:$AMK$3,3,MATCH(H23,PitRawData!$A$1:$AMK$1,0)),"NO DATA") -> NO DATA | C23: =IFERROR(INDEX(PitRawData!$A$1:$AMK$3,3,MATCH(I23,PitRawData!$A$1:$AMK$1,0)),"NO DATA") -> NO DATA | D23: =IFERROR(INDEX(PitRawData!$A$1:$AMK$3,3,MATCH(J23,PitRawData!$A$1:$AMK$1,0)),"NO DATA") -> NO DATA | E23: =IFERROR(INDEX(PitRawData!$A$1:$AMK$3,3,MATCH(K23,PitRawData!$A$1:$AMK$1,0)),"NO DATA") -> NO DATA | F23: =SUM(B23:E23) -> 0 | H23: personYouthHispanicEmergency | I23: personYouthHispanicTransitional | J23: personYouthHispanicSafeHaven | K23: personYouthHispanicUnsheltered
A24: Middle Eastern or North African (only) | B24: =IFERROR(INDEX(PitRawData!$A$1:$AMK$3,3,MATCH(H24,PitRawData!$A$1:$AMK$1,0)),"NO DATA") -> NO DATA | C24: =IFERROR(INDEX(PitRawData!$A$1:$AMK$3,3,MATCH(I24,PitRawData!$A$1:$AMK$1,0)),"NO DATA") -> NO DATA | D24: =IFERROR(INDEX(PitRawData!$A$1:$AMK$3,3,MATCH(J24,PitRawData!$A$1:$AMK$1,0)),"NO DATA") -> NO DATA | E24: =IFERROR(INDEX(PitRawData!$A$1:$AMK$3,3,MATCH(K24,PitRawData!$A$1:$AMK$1,0)),"NO DATA") -> NO DATA | F24: =SUM(B24:E24) -> 0 | H24: personYouthMENANHEmergency | I24: personYouthMENANHTransitional | J24: personYouthMENANHSafeHaven | K24: personYouthMENANHUnsheltered
A25: Middle Eastern or North African & Hispanic/Latina/e/o | B25: =IFERROR(INDEX(PitRawData!$A$1:$AMK$3,3,MATCH(H25,PitRawData!$A$1:$AMK$1,0)),"NO DATA") -> NO DATA | C25: =IFERROR(INDEX(PitRawData!$A$1:$AMK$3,3,MATCH(I25,PitRawData!$A$1:$AMK$1,0)),"NO DATA") -> NO DATA | D25: =IFERROR(INDEX(PitRawData!$A$1:$AMK$3,3,MATCH(J25,PitRawData!$A$1:$AMK$1,0)),"NO DATA") -> NO DATA | E25: =IFERROR(INDEX(PitRawData!$A$1:$AMK$3,3,MATCH(K25,PitRawData!$A$1:$AMK$1,0)),"NO DATA") -> NO DATA | F25: =SUM(B25:E25) -> 0 | H25: personYouthMENAHEmergency | I25: personYouthMENAHTransitional | J25: personYouthMENAHSafeHaven | K25: personYouthMENAHUnsheltered
A26: Native Hawaiian or Pacific Islander (only) | B26: =IFERROR(INDEX(PitRawData!$A$1:$AMK$3,3,MATCH(H26,PitRawData!$A$1:$AMK$1,0)),"NO DATA") -> NO DATA | C26: =IFERROR(INDEX(PitRawData!$A$1:$AMK$3,3,MATCH(I26,PitRawData!$A$1:$AMK$1,0)),"NO DATA") -> NO DATA | D26: =IFERROR(INDEX(PitRawData!$A$1:$AMK$3,3,MATCH(J26,PitRawData!$A$1:$AMK$1,0)),"NO DATA") -> NO DATA | E26: =IFERROR(INDEX(PitRawData!$A$1:$AMK$3,3,MATCH(K26,PitRawData!$A$1:$AMK$1,0)),"NO DATA") -> NO DATA | F26: =SUM(B26:E26) -> 0 | H26: personYouthNativeHawaiianNHEmergency | I26: personYouthNativeHawaiianNHTransitional | J26: personYouthNativeHawaiianNHSafeHaven | K26: personYouthNativeHawaiianNHUnsheltered
A27: Native Hawaiian or Pacific Islander & Hispanic/Latina/e/o | B27: =IFERROR(INDEX(PitRawData!$A$1:$AMK$3,3,MATCH(H27,PitRawData!$A$1:$AMK$1,0)),"NO DATA") -> NO DATA | C27: =IFERROR(INDEX(PitRawData!$A$1:$AMK$3,3,MATCH(I27,PitRawData!$A$1:$AMK$1,0)),"NO DATA") -> NO DATA | D27: =IFERROR(INDEX(PitRawData!$A$1:$AMK$3,3,MATCH(J27,PitRawData!$A$1:$AMK$1,0)),"NO DATA") -> NO DATA | E27: =IFERROR(INDEX(PitRawData!$A$1:$AMK$3,3,MATCH(K27,PitRawData!$A$1:$AMK$1,0)),"NO DATA") -> NO DATA | F27: =SUM(B27:E27) -> 0 | H27: personYouthNativeHawaiianHEmergency | I27: personYouthNativeHawaiianHTransitional | J27: personYouthNativeHawaiianHSafeHaven | K27: personYouthNativeHawaiianHUnsheltered
A28: White (only) | B28: =IFERROR(INDEX(PitRawData!$A$1:$AMK$3,3,MATCH(H28,PitRawData!$A$1:$AMK$1,0)),"NO DATA") -> NO DATA | C28: =IFERROR(INDEX(PitRawData!$A$1:$AMK$3,3,MATCH(I28,PitRawData!$A$1:$AMK$1,0)),"NO DATA") -> NO DATA | D28: =IFERROR(INDEX(PitRawData!$A$1:$AMK$3,3,MATCH(J28,PitRawData!$A$1:$AMK$1,0)),"NO DATA") -> NO DATA | E28: =IFERROR(INDEX(PitRawData!$A$1:$AMK$3,3,MATCH(K28,PitRawData!$A$1:$AMK$1,0)),"NO DATA") -> NO DATA | F28: =SUM(B28:E28) -> 0 | H28: personYouthWhiteNHEmergency | I28: personYouthWhiteNHTransitional | J28: personYouthWhiteNHSafeHaven | K28: personYouthWhiteNHUnsheltered
... A31: Multi-Racial (all other) | B31: =IFERROR(INDEX(PitRawData!$A$1:$AMK$3,3,MATCH(H31,PitRawData!$A$1:$AMK$1,0)),"NO DATA") -> NO DATA | C31: =IFERROR(INDEX(PitRawData!$A$1:$AMK$3,3,MATCH(I31,PitRawData!$A$1:$AMK$1,0)),"NO DATA") -> NO DATA | D31: =IFERROR(INDEX(PitRawData!$A$1:$AMK$3,3,MATCH(J31,PitRawData!$A$1:$AMK$1,0)),"NO DATA") -> NO DATA | E31: =IFERROR(INDEX(PitRawData!$A$1:$AMK$3,3,MATCH(K31,PitRawData!$A$1:$AMK$1,0)),"NO DATA") -> NO DATA | F31: =SUM(B31:E31) -> 0 | H31: personYouthMultipleRaceNHEmergency | I31: personYouthMultipleRaceNHTransitional | J31: personYouthMultipleRaceNHSafeHaven | K31: personYouthMultipleRaceNHUnsheltered
B33: Sheltered | E33: Unsheltered | F33: Total
A34: Chronically Homeless | B34: Emergency | C34: Transitional | D34: Safe Haven
A35: Total number of persons | B35: =IFERROR(INDEX(PitRawData!$A$1:$AMK$3,3,MATCH(H35,PitRawData!$A$1:$AMK$1,0)),"NO DATA") -> NO DATA | C35: N/A | D35: =IFERROR(INDEX(PitRawData!$A$1:$AMK$3,3,MATCH(J35,PitRawData!$A$1:$AMK$1,0)),"NO DATA") -> NO DATA | E35: =IFERROR(INDEX(PitRawData!$A$1:$AMK$3,3,MATCH(K35,PitRawData!$A$1:$AMK$1,0)),"NO DATA") -> NO DATA | F35: =SUM(B35,D35,E35) -> 0 | H35: personYouthCronPersonsEmergency | J35: personYouthCronPersonsSafeHaven | K35: personYouthCronPersonsUnsheltered

Sheet Youth_PY
A1: PIT Summary Report
A2: =HeadingLine2
A3: =HeadingLine3 -> PASTE DATA INTO THE 'PitRawData' TAB TO POPULATE THIS TEMPLATE.
A4: =HeadingLine4
A6: Youth Subpopulation: Parenting Youth Households ("Youth PY")
B8: Sheltered | D8: Unsheltered | E8: Total
A9: Persons and Households | B9: Emergency | C9: Transitional
A10: Total number of parenting youth households | B10: =IFERROR(INDEX(PitRawData!$A$1:$AMK$3,3,MATCH(G10,PitRawData!$A$1:$AMK$1,0)),"NO DATA") -> NO DATA | C10: =IFERROR(INDEX(PitRawData!$A$1:$AMK$3,3,MATCH(H10,PitRawData!$A$1:$AMK$1,0)),"NO DATA") -> NO DATA | D10: =IFERROR(INDEX(PitRawData!$A$1:$AMK$3,3,MATCH(I10,PitRawData!$A$1:$AMK$1,0)),"NO DATA") -> NO DATA | E10: =SUM(B10:D10) -> 0 | G10: householdParentingYouthEmergency | H10: householdParentingYouthTransitional | I10: householdParentingYouthUnsheltered
A11: Total number of persons in parenting youth households | B11: =SUM(B14:B17) -> 0 | C11: =SUM(C14:C17) -> 0 | D11: =SUM(D14:D17) -> 0 | E11: =SUM(B11:D11) -> 0
A12: Total Parenting Youth (youth parents only) | B12: =B14+B16 -> #VALUE! | C12: =C14+C16 -> #VALUE! | D12: =D14+D16 -> #VALUE! | E12: =SUM(B12:D12) -> #VALUE!
A13: Total Children in Parenting Youth Households | B13: =B15+B17 -> #VALUE! | C13: =C15+C17 -> #VALUE! | D13: =D15+D17 -> #VALUE! | E13: =SUM(B13:D13) -> #VALUE!
A14: Number of parenting youth (under 18) | B14: =IFERROR(INDEX(PitRawData!$A$1:$AMK$3,3,MATCH(G14,PitRawData!$A$1:$AMK$1,0)),"NO DATA") -> NO DATA | C14: =IFERROR(INDEX(PitRawData!$A$1:$AMK$3,3,MATCH(H14,PitRawData!$A$1:$AMK$1,0)),"NO DATA") -> NO DATA | D14: =IFERROR(INDEX(PitRawData!$A$1:$AMK$3,3,MATCH(I14,PitRawData!$A$1:$AMK$1,0)),"NO DATA") -> NO DATA | E14: =SUM(B14:D14) -> 0 | G14: personParentingYouthUnder18Emergency | H14: personParentingYouthUnder18Transitional | I14: personParentingYouthUnder18Unsheltered
A15: Children in households with parenting youth under 18 (children under age 18 with parents under 18) | B15: =IFERROR(INDEX(PitRawData!$A$1:$AMK$3,3,MATCH(G15,PitRawData!$A$1:$AMK$1,0)),"NO DATA") -> NO DATA | C15: =IFERROR(INDEX(PitRawData!$A$1:$AMK$3,3,MATCH(H15,PitRawData!$A$1:$AMK$1,0)),"NO DATA") -> NO DATA | D15: =IFERROR(INDEX(PitRawData!$A$1:$AMK$3,3,MATCH(I15,PitRawData!$A$1:$AMK$1,0)),"NO DATA") -> NO DATA | E15: =SUM(B15:D15) -> 0 | G15: personParentingYouthChildrenParentsUnder18Emergency | H15: personParentingYouthChildrenParentsUnder18Transitional | I15: personParentingYouthChildrenParentsUnder18Unsheltered
A16: Number of parenting youth (18 - 24) | B16: =IFERROR(INDEX(PitRawData!$A$1:$AMK$3,3,MATCH(G16,PitRawData!$A$1:$AMK$1,0)),"NO DATA") -> NO DATA | C16: =IFERROR(INDEX(PitRawData!$A$1:$AMK$3,3,MATCH(H16,PitRawData!$A$1:$AMK$1,0)),"NO DATA") -> NO DATA | D16: =IFERROR(INDEX(PitRawData!$A$1:$AMK$3,3,MATCH(I16,PitRawData!$A$1:$AMK$1,0)),"NO DATA") -> NO DATA | E16: =SUM(B16:D16) -> 0 | G16: personParentingYouth18To24Emergency | H16: personParentingYouth18To24Transitional | I16: personParentingYouth18To24Unsheltered
A17: Children in households with parenting youth 18 - 24 (children under age 18 with parents age 18 to 24) | B17: =IFERROR(INDEX(PitRawData!$A$1:$AMK$3,3,MATCH(G17,PitRawData!$A$1:$AMK$1,0)),"NO DATA") -> NO DATA | C17: =IFERROR(INDEX(PitRawData!$A$1:$AMK$3,3,MATCH(H17,PitRawData!$A$1:$AMK$1,0)),"NO DATA") -> NO DATA | D17: =IFERROR(INDEX(PitRawData!$A$1:$AMK$3,3,MATCH(I17,PitRawData!$A$1:$AMK$1,0)),"NO DATA") -> NO DATA | E17: =SUM(B17:D17) -> 0 | G17: personParentingYouthChildrenParents18To24Emergency | H17: personParentingYouthChildrenParents18To24Transitional | I17: personParentingYouthChildrenParents18To24Unsheltered
B19: Sheltered | D19: Unsheltered | E19: Total
A20: Race/Ethnicity (Youth Parents Only) | B20: Emergency | C20: Transitional
